<?xml version="1.0"?>
<!-- =================================================================================== -->
<!-- |    This document was autogenerated by xacro from
/home/kisdy/projects/agv_localization_ws/install/jzt_robot/share/jzt_robot/urdf/mecanum/robot.xacro
| -->
<!-- |    EDITING THIS FILE BY HAND IS NOT RECOMMENDED                                 | -->
<!-- =================================================================================== -->
<robot name="jzMecanumRobot">
    <!-- 颜色定义 -->
    <material name="white">
        <color rgba="0.95 0.95 0.95 1.0" />
    </material>
    <material name="purple">
        <color rgba="0.5 0.0 0.5 1.0" />
    </material>
    <material name="black">
        <color rgba="0.1 0.1 0.1 1.0" />
    </material>
    <material name="dark_grey">
        <color rgba="0.3 0.3 0.3 1.0" />
    </material>
    <!-- <xacro:include filename="common_properties.xacro" /> -->
    <!-- base_footprint -->
    <link name="base_footprint" />
    <joint name="base_joint" type="fixed">
        <parent link="base_footprint" />
        <child link="base_link" />
        <origin rpy="0 0 0" xyz="0 0 0.108" />
    </joint>
    <link name="base_link">
        <visual>
            <origin rpy="0 0 0" xyz="0 0 0.14" />
            <geometry>
                <box size="1.1 0.56 0.28" />
            </geometry>
            <material name="white" />
        </visual>
        <collision>
            <origin rpy="0 0 0" xyz="0 0 0.14" />
            <geometry>
                <box size="1.1 0.56 0.28" />
            </geometry>
        </collision>
        <inertial>
            <mass value="15.0" />
            <inertia ixx="0.49000000000000005" ixy="0" ixz="0" iyy="1.6105000000000003" iyz="0"
                izz="1.9045000000000003" />
        </inertial>
    </link>
    <!-- 激光 -->
    <joint name="laser_joint" type="fixed">
        <parent link="base_link" />
        <child link="laser_link" />
        <origin rpy="0 0 0" xyz="0.40 0 0.32" />
    </joint>
    <link name="laser_link">
        <visual>
            <geometry>
                <cylinder length="0.08" radius="0.04" />
            </geometry>
            <material name="purple" />
        </visual>
        <collision>
            <geometry>
                <cylinder length="0.08" radius="0.04" />
            </geometry>
        </collision>
        <inertial>
            <mass value="0.3" />
            <inertia ixx="0.0002" ixy="0" ixz="0" iyy="0.0002" iyz="0" izz="0.00024" />
        </inertial>
    </link>
    <!-- 相机 -->
    <joint name="camera_joint" type="fixed">
        <parent link="base_link" />
        <child link="camera_link" />
        <origin rpy="0 0 0" xyz="0.536 0 0.14" />
    </joint>
    <link name="camera_link">
        <visual>
            <geometry>
                <box size="0.03 0.12 0.03" />
            </geometry>
            <material name="black" />
        </visual>
        <collision>
            <geometry>
                <box size="0.03 0.12 0.03" />
            </geometry>
        </collision>
        <inertial>
            <mass value="0.2" />
            <inertia ixx="0.0001" ixy="0" ixz="0" iyy="0.0002" iyz="0" izz="0.0002" />
        </inertial>
    </link>
    <link name="camera_optical_link" />
    <joint name="camera_optical_joint" type="fixed">
        <parent link="camera_link" />
        <child link="camera_optical_link" />
        <origin rpy="-1.570796327 0 -1.570796327" xyz="0.015 0 0" />
    </joint>
    <!-- IMU -->
    <joint name="imu_joint" type="fixed">
        <parent link="base_link" />
        <child link="imu_link" />
        <origin rpy="0 0 0" xyz="0 0 0.14" />
    </joint>
    <link name="imu_link">
        <visual>
            <geometry>
                <box size="0.02 0.02 0.02" />
            </geometry>
        </visual>
        <collision>
            <geometry>
                <box size="0.02 0.02 0.02" />
            </geometry>
        </collision>
        <inertial>
            <mass value="0.1" />
            <inertia ixx="3e-6" ixy="0" ixz="0" iyy="3e-6" iyz="0" izz="3e-6" />
        </inertial>
    </link>
    <!-- <xacro:include filename="common_properties.xacro" /> -->
    <joint name="front_left_wheel_joint" type="continuous">
        <parent link="base_link" />
        <child link="front_left_wheel_link" />
        <origin rpy="0 0 0" xyz="0.4 0.28 0.0" />
        <axis xyz="0 1 0" />
    </joint>
    <link name="front_left_wheel_link">
        <visual>
            <origin rpy="0 0 0" xyz="0 0 0" />
            <geometry>
                <!-- 使用 package:// 路径 + 参数化的 STL 文件名 -->
                <mesh
                    filename="/home/kisdy/projects/agv_localization_ws/install/jzt_robot/share/jzt_robot/meshes/fl_wheel_link.STL"
                    scale="1.0 1.0 1.0" />
            </geometry>
            <material name="dark_grey" />
        </visual>
        <collision>
            <origin rpy="0 0 0" xyz="0 0 0" />
            <geometry>
                <!-- 仍使用圆柱体碰撞模型，保证物理稳定 -->
                <cylinder length="0.08" radius="0.108" />
            </geometry>
        </collision>
        <inertial>
            <mass value="1.2" />
            <inertia ixx="0.0041392" ixy="0" ixz="0" iyy="0.0041392" iyz="0"
                izz="0.006998399999999999" />
        </inertial>
    </link>
    <joint name="front_right_wheel_joint" type="continuous">
        <parent link="base_link" />
        <child link="front_right_wheel_link" />
        <origin rpy="0 0 0" xyz="0.4 -0.28 0.0" />
        <axis xyz="0 1 0" />
    </joint>
    <link name="front_right_wheel_link">
        <visual>
            <origin rpy="0 0 0" xyz="0 0 0" />
            <geometry>
                <!-- 使用 package:// 路径 + 参数化的 STL 文件名 -->
                <mesh
                    filename="/home/kisdy/projects/agv_localization_ws/install/jzt_robot/share/jzt_robot/meshes/fr_wheel_link.STL"
                    scale="1.0 1.0 1.0" />
            </geometry>
            <material name="dark_grey" />
        </visual>
        <collision>
            <origin rpy="0 0 0" xyz="0 0 0" />
            <geometry>
                <!-- 仍使用圆柱体碰撞模型，保证物理稳定 -->
                <cylinder length="0.08" radius="0.108" />
            </geometry>
        </collision>
        <inertial>
            <mass value="1.2" />
            <inertia ixx="0.0041392" ixy="0" ixz="0" iyy="0.0041392" iyz="0"
                izz="0.006998399999999999" />
        </inertial>
    </link>
    <joint name="rear_left_wheel_joint" type="continuous">
        <parent link="base_link" />
        <child link="rear_left_wheel_link" />
        <origin rpy="0 0 0" xyz="-0.4 0.28 0.0" />
        <axis xyz="0 1 0" />
    </joint>
    <link name="rear_left_wheel_link">
        <visual>
            <origin rpy="0 0 0" xyz="0 0 0" />
            <geometry>
                <!-- 使用 package:// 路径 + 参数化的 STL 文件名 -->
                <mesh
                    filename="/home/kisdy/projects/agv_localization_ws/install/jzt_robot/share/jzt_robot/meshes/rl_wheel_link.STL"
                    scale="1.0 1.0 1.0" />
            </geometry>
            <material name="dark_grey" />
        </visual>
        <collision>
            <origin rpy="0 0 0" xyz="0 0 0" />
            <geometry>
                <!-- 仍使用圆柱体碰撞模型，保证物理稳定 -->
                <cylinder length="0.08" radius="0.108" />
            </geometry>
        </collision>
        <inertial>
            <mass value="1.2" />
            <inertia ixx="0.0041392" ixy="0" ixz="0" iyy="0.0041392" iyz="0"
                izz="0.006998399999999999" />
        </inertial>
    </link>
    <joint name="rear_right_wheel_joint" type="continuous">
        <parent link="base_link" />
        <child link="rear_right_wheel_link" />
        <origin rpy="0 0 0" xyz="-0.4 -0.28 0.0" />
        <axis xyz="0 1 0" />
    </joint>
    <link name="rear_right_wheel_link">
        <visual>
            <origin rpy="0 0 0" xyz="0 0 0" />
            <geometry>
                <!-- 使用 package:// 路径 + 参数化的 STL 文件名 -->
                <mesh
                    filename="/home/kisdy/projects/agv_localization_ws/install/jzt_robot/share/jzt_robot/meshes/rr_wheel_link.STL"
                    scale="1.0 1.0 1.0" />
            </geometry>
            <material name="dark_grey" />
        </visual>
        <collision>
            <origin rpy="0 0 0" xyz="0 0 0" />
            <geometry>
                <!-- 仍使用圆柱体碰撞模型，保证物理稳定 -->
                <cylinder length="0.08" radius="0.108" />
            </geometry>
        </collision>
        <inertial>
            <mass value="1.2" />
            <inertia ixx="0.0041392" ixy="0" ixz="0" iyy="0.0041392" iyz="0"
                izz="0.006998399999999999" />
        </inertial>
    </link>
    <gazebo reference="front_left_wheel_link">
        <material>Gazebo/DarkGrey</material>
        <collision>
            <surface>
                <friction>
                    <ode>
                        <mu1>0.8</mu1>
                        <mu2>0.3</mu2>
                        <fdir1>
                            <x>-0.7071</x>
                            <y>0.7071</y>
                            <z>0.0</z>
                        </fdir1>
                        <kp value="10000000.0" />
                        <kd value="1.0" />
                    </ode>
                </friction>
                <contact>
                    <ode>
                        <kp>1e7</kp>
                        <kd>1.0</kd>
                        <min_depth>0.001</min_depth>
                    </ode>
                </contact>
            </surface>
        </collision>
    </gazebo>
    <gazebo reference="front_right_wheel_link">
        <material>Gazebo/DarkGrey</material>
        <collision>
            <surface>
                <friction>
                    <ode>
                        <mu1>0.8</mu1>
                        <mu2>0.3</mu2>
                        <fdir1>
                            <x>-0.7071</x>
                            <y>-0.7071</y>
                            <z>0.0</z>
                        </fdir1>
                        <kp value="10000000.0" />
                        <kd value="1.0" />
                    </ode>
                </friction>
                <contact>
                    <ode>
                        <kp>1e7</kp>
                        <kd>1.0</kd>
                        <min_depth>0.001</min_depth>
                    </ode>
                </contact>
            </surface>
        </collision>
    </gazebo>
    <gazebo reference="rear_left_wheel_link">
        <material>Gazebo/DarkGrey</material>
        <collision>
            <surface>
                <friction>
                    <ode>
                        <mu1>0.8</mu1>
                        <mu2>0.3</mu2>
                        <fdir1>
                            <x>-0.7071</x>
                            <y>-0.7071</y>
                            <z>0.0</z>
                        </fdir1>
                        <kp value="10000000.0" />
                        <kd value="1.0" />
                    </ode>
                </friction>
                <contact>
                    <ode>
                        <kp>1e7</kp>
                        <kd>1.0</kd>
                        <min_depth>0.001</min_depth>
                    </ode>
                </contact>
            </surface>
        </collision>
    </gazebo>
    <gazebo reference="rear_right_wheel_link">
        <material>Gazebo/DarkGrey</material>
        <collision>
            <surface>
                <friction>
                    <ode>
                        <mu1>0.8</mu1>
                        <mu2>0.3</mu2>
                        <fdir1>
                            <x>-0.7071</x>
                            <y>0.7071</y>
                            <z>0.0</z>
                        </fdir1>
                        <kp value="10000000.0" />
                        <kd value="1.0" />
                    </ode>
                </friction>
                <contact>
                    <ode>
                        <kp>1e7</kp>
                        <kd>1.0</kd>
                        <min_depth>0.001</min_depth>
                    </ode>
                </contact>
            </surface>
        </collision>
    </gazebo>
    <!-- 激光 -->
    <gazebo reference="laser_link">
        <material>Gazebo/Purple</material>
        <sensor name="laser_sensor" type="ray">
            <always_on>true</always_on>
            <visualize>true</visualize>
            <update_rate>20</update_rate>
            <pose>0 0 0 0 0 0</pose>
            <ray>
                <scan>
                    <horizontal>
                        <samples>720</samples>
                        <resolution>1.0</resolution>
                        <time_increment>0.000069</time_increment>
                        <min_angle>-3.14159</min_angle>
                        <max_angle>3.14159</max_angle>
                    </horizontal>
                </scan>
                <range>
                    <min>0.15</min>
                    <max>15.0</max>
                    <resolution>0.01</resolution>
                </range>
                <noise>
                    <type>gaussian</type>
                    <mean>0.0</mean>
                    <stddev>0.001</stddev>
                </noise>
            </ray>
            <plugin filename="libgazebo_ros_ray_sensor.so" name="gazebo_ros_head_laser_controller">
                <ros>
                    <remapping>~/out:=scan</remapping>
                </ros>
                <output_type>sensor_msgs/LaserScan</output_type>
                <frame_name>laser_link</frame_name>
            </plugin>
        </sensor>
    </gazebo>
    <!-- 相机 -->
    <gazebo reference="camera_link">
        <material>Gazebo/Black</material>
        <sensor name="camera_sensor" type="camera">
            <camera>
                <horizontal_fov>1.047</horizontal_fov>
                <image>
                    <width>640</width>
                    <height>480</height>
                    <format>R8G8B8</format>
                </image>
                <clip>
                    <near>0.1</near>
                    <far>100</far>
                </clip>
            </camera>
            <always_on>true</always_on>
            <update_rate>30</update_rate>
            <visualize>true</visualize>
            <plugin filename="libgazebo_ros_camera.so" name="camera_plugin">
                <ros>
                    <remapping>~/image:=camera/image_raw</remapping>
                    <remapping>~/camera_info:=camera/camera_info</remapping>
                </ros>
                <camera_name>camera</camera_name>
                <frame_name>camera_optical_link</frame_name>
                <hack_baseline>0.07</hack_baseline>
            </plugin>
        </sensor>
    </gazebo>
    <!-- IMU -->
    <gazebo reference="imu_link">
        <material>Gazebo/Purple</material>
        <sensor name="imu_sensor" type="imu">
            <always_on>true</always_on>
            <update_rate>100</update_rate>
            <visualize>true</visualize>
            <plugin filename="libgazebo_ros_imu_sensor.so" name="imu_plugin">
                <ros>
                    <remapping>~/out:=imu</remapping>
                </ros>
                <initial_orientation_as_reference>false</initial_orientation_as_reference>
                <frame_name>imu_link</frame_name>
            </plugin>
        </sensor>
    </gazebo>
    <!-- <xacro:include filename="common_properties.xacro" /> -->
    <ros2_control name="GazeboSystem" type="system">
        <hardware>
            <plugin>gazebo_ros2_control/GazeboSystem</plugin>
        </hardware>
        <joint name="front_left_wheel_joint">
            <command_interface name="velocity" />
            <state_interface name="position" />
            <state_interface name="velocity" />
        </joint>
        <joint name="front_right_wheel_joint">
            <command_interface name="velocity" />
            <state_interface name="position" />
            <state_interface name="velocity" />
        </joint>
        <joint name="rear_left_wheel_joint">
            <command_interface name="velocity" />
            <state_interface name="position" />
            <state_interface name="velocity" />
        </joint>
        <joint name="rear_right_wheel_joint">
            <command_interface name="velocity" />
            <state_interface name="position" />
            <state_interface name="velocity" />
        </joint>
    </ros2_control>
    <!-- Gazebo 加载控制器的插件 -->
    <gazebo>
        <plugin filename="libgazebo_ros2_control.so" name="gazebo_ros2_control">
            <parameters>
                /home/kisdy/projects/agv_localization_ws/install/jzt_robot/share/jzt_robot/config/mecanum_controllers.yaml</parameters>
        </plugin>
    </gazebo>
    <!-- 原 URDF 中的全局物理设置 -->
    <gazebo>
        <physics type="ode">
            <max_step_size>0.001</max_step_size>
            <real_time_factor>1.0</real_time_factor>
            <real_time_update_rate>1000</real_time_update_rate>
        </physics>
    </gazebo>
</robot>