<?xml version="1.0"?>
<robot name="jzMecanumRobot">

    <link name="base_footprint" />

    <joint name="base_joint" type="fixed">
        <parent link="base_footprint" />
        <child link="base_link" />
        <origin xyz="0.0 0.0 0.108" rpy="0 0 0" />
    </joint>

    <link name="base_link">
        <visual>
            <origin xyz="0 0 0.14" rpy="0 0 0" />
            <geometry>
                <box size="1.1 0.56 0.28" />
            </geometry>
            <material name="white">
                <color rgba="0.95 0.95 0.95 1.0" />
            </material>
        </visual>
        <collision>
            <origin xyz="0 0 0.14" rpy="0 0 0" />
            <geometry>
                <box size="1.1 0.56 0.28" />
            </geometry>
        </collision>
        <inertial>
            <mass value="15.0" />
            <inertia ixx="0.35" ixy="0" ixz="0" iyy="0.95" iyz="0" izz="1.25" />
        </inertial>
    </link>

    <gazebo reference="base_link">
        <material>Gazebo/White</material>
    </gazebo>

    <link name="laser_link">
        <visual>
            <origin xyz="0 0 0" rpy="0 0 0" />
            <geometry>
                <cylinder length="0.08" radius="0.04" />
            </geometry>
            <material name="purple">
                <color rgba="0.5 0.0 0.5 1.0" />
            </material>
        </visual>
        <collision>
            <origin xyz="0 0 0" rpy="0 0 0" />
            <geometry>
                <cylinder length="0.08" radius="0.04" />
            </geometry>
        </collision>
        <inertial>
            <mass value="0.3" />
            <inertia ixx="0.0002" ixy="0" ixz="0" iyy="0.0002" iyz="0" izz="0.00024" />
        </inertial>
    </link>

    <joint name="laser_joint" type="fixed">
        <parent link="base_link" />
        <child link="laser_link" />
        <origin xyz="0.40 0 0.32" rpy="0 0 0" />
    </joint>

    <gazebo reference="laser_link">
        <material>Gazebo/Purple</material>
    </gazebo>

    <link name="camera_link">
        <visual>
            <origin xyz="0 0 0" rpy="0 0 0" />
            <geometry>
                <box size="0.03 0.12 0.03" />
            </geometry>
            <material name="black">
                <color rgba="0.1 0.1 0.1 1.0" />
            </material>
        </visual>
        <collision>
            <origin xyz="0 0 0" rpy="0 0 0" />
            <geometry>
                <box size="0.03 0.12 0.03" />
            </geometry>
        </collision>
        <inertial>
            <mass value="0.2" />
            <inertia ixx="0.0001" ixy="0" ixz="0" iyy="0.0002" iyz="0" izz="0.0002" />
        </inertial>
    </link>

    <link name="camera_optical_link"></link>

    <joint name="camera_joint" type="fixed">
        <parent link="base_link" />
        <child link="camera_link" />
        <origin xyz="0.536 0 0.14" rpy="0 0 0" />
    </joint>

    <joint name="camera_optical_joint" type="fixed">
        <parent link="camera_link" />
        <child link="camera_optical_link" />
        <origin xyz="0.015 0 0" rpy="-1.570796 0 -1.570796" />
    </joint>

    <gazebo reference="camera_link">
        <material>Gazebo/Black</material>
        <sensor name="camera_sensor" type="camera">
            <camera>
                <horizontal_fov>1.047</horizontal_fov>
                <image>
                    <width>640</width>
                    <height>480</height>
                    <format>R8G8B8</format>
                </image>
                <clip>
                    <near>0.1</near>
                    <far>100</far>
                </clip>
            </camera>
            <always_on>true</always_on>
            <update_rate>30</update_rate>
            <visualize>true</visualize>
            <plugin name="camera_plugin" filename="libgazebo_ros_camera.so">
                <ros>
                    <remapping>~/image:=camera/image_raw</remapping>
                    <remapping>~/camera_info:=camera/camera_info</remapping>
                </ros>
                <camera_name>camera</camera_name>
                <frame_name>camera_optical_link</frame_name>
                <hack_baseline>0.07</hack_baseline>
            </plugin>
        </sensor>
    </gazebo>

    <link name="imu_link">
        <visual>
            <geometry>
                <box size="0.02 0.02 0.02" />
            </geometry>
        </visual>
        <collision>
            <geometry>
                <box size="0.02 0.02 0.02" />
            </geometry>
        </collision>
        <inertial>
            <mass value="0.1" />
            <inertia ixx="0.000003" ixy="0" ixz="0" iyy="0.000003" iyz="0" izz="0.000003" />
        </inertial>
    </link>

    <joint name="imu_joint" type="fixed">
        <origin xyz="0 0 0.14" rpy="0 0 0" />
        <parent link="base_link" />
        <child link="imu_link" />
    </joint>

    <gazebo reference="imu_link">
        <material>Gazebo/Purple</material>
        <sensor name="imu_sensor" type="imu">
            <plugin filename="libgazebo_ros_imu_sensor.so" name="imu_plugin">
                <ros>
                    <remapping>~/out:=imu</remapping>
                </ros>
                <initial_orientation_as_reference>false</initial_orientation_as_reference>
                <frame_name>imu_link</frame_name>
            </plugin>
            <always_on>true</always_on>
            <update_rate>100</update_rate>
            <visualize>true</visualize>
            <imu>
                <angular_velocity>
                    <x>
                        <noise type="gaussian">
                            <mean>0.0</mean>
                            <stddev>2e-4</stddev>
                            <bias_mean>0.0000075</bias_mean>
                            <bias_stddev>0.0000008</bias_stddev>
                        </noise>
                    </x>
                    <y>
                        <noise type="gaussian">
                            <mean>0.0</mean>
                            <stddev>2e-4</stddev>
                            <bias_mean>0.0000075</bias_mean>
                            <bias_stddev>0.0000008</bias_stddev>
                        </noise>
                    </y>
                    <z>
                        <noise type="gaussian">
                            <mean>0.0</mean>
                            <stddev>2e-4</stddev>
                            <bias_mean>0.0000075</bias_mean>
                            <bias_stddev>0.0000008</bias_stddev>
                        </noise>
                    </z>
                </angular_velocity>
                <linear_acceleration>
                    <x>
                        <noise type="gaussian">
                            <mean>0.0</mean>
                            <stddev>1.7e-2</stddev>
                            <bias_mean>0.1</bias_mean>
                            <bias_stddev>0.001</bias_stddev>
                        </noise>
                    </x>
                    <y>
                        <noise type="gaussian">
                            <mean>0.0</mean>
                            <stddev>1.7e-2</stddev>
                            <bias_mean>0.1</bias_mean>
                            <bias_stddev>0.001</bias_stddev>
                        </noise>
                    </y>
                    <z>
                        <noise type="gaussian">
                            <mean>0.0</mean>
                            <stddev>1.7e-2</stddev>
                            <bias_mean>0.1</bias_mean>
                            <bias_stddev>0.001</bias_stddev>
                        </noise>
                    </z>
                </linear_acceleration>
            </imu>
        </sensor>
    </gazebo>


    <link name="front_left_wheel_link">
        <visual>
            <origin xyz="0 0 0" rpy="1.57079 0 0" />
            <geometry>
                <cylinder length="0.08" radius="0.108" />
            </geometry>
            <material name="mecanum_wheel">
                <color rgba="0.2 0.2 0.2 1.0" />
            </material>
        </visual>
        <visual>
            <origin xyz="0 0 0" rpy="0.785398 1.57079 0" />
            <geometry>
                <box size="0.15 0.02 0.02" />
            </geometry>
            <material name="roller">
                <color rgba="0.4 0.4 0.4 1.0" />
            </material>
        </visual>
        <collision>
            <origin xyz="0 0 0" rpy="1.57079 0 0" />
            <geometry>
                <cylinder length="0.08" radius="0.108" />
            </geometry>
        </collision>
        <inertial>
            <mass value="1.2" />
            <inertia ixx="0.0025" ixy="0" ixz="0" iyy="0.0025" iyz="0" izz="0.0045" />
        </inertial>
    </link>

    <link name="front_right_wheel_link">
        <visual>
            <origin xyz="0 0 0" rpy="1.57079 0 0" />
            <geometry>
                <cylinder length="0.08" radius="0.108" />
            </geometry>
            <material name="mecanum_wheel">
                <color rgba="0.2 0.2 0.2 1.0" />
            </material>
        </visual>
        <visual>
            <origin xyz="0 0 0" rpy="-0.785398 1.57079 0" />
            <geometry>
                <box size="0.15 0.02 0.02" />
            </geometry>
            <material name="roller">
                <color rgba="0.4 0.4 0.4 1.0" />
            </material>
        </visual>
        <collision>
            <origin xyz="0 0 0" rpy="1.57079 0 0" />
            <geometry>
                <cylinder length="0.08" radius="0.108" />
            </geometry>
        </collision>
        <inertial>
            <mass value="1.2" />
            <inertia ixx="0.0025" ixy="0" ixz="0" iyy="0.0025" iyz="0" izz="0.0045" />
        </inertial>
    </link>

    <link name="rear_left_wheel_link">
        <visual>
            <origin xyz="0 0 0" rpy="1.57079 0 0" />
            <geometry>
                <cylinder length="0.08" radius="0.108" />
            </geometry>
            <material name="mecanum_wheel">
                <color rgba="0.2 0.2 0.2 1.0" />
            </material>
        </visual>
        <visual>
            <origin xyz="0 0 0" rpy="-0.785398 1.57079 0" />
            <geometry>
                <box size="0.15 0.02 0.02" />
            </geometry>
            <material name="roller">
                <color rgba="0.4 0.4 0.4 1.0" />
            </material>
        </visual>
        <collision>
            <origin xyz="0 0 0" rpy="1.57079 0 0" />
            <geometry>
                <cylinder length="0.08" radius="0.108" />
            </geometry>
        </collision>
        <inertial>
            <mass value="1.2" />
            <inertia ixx="0.0025" ixy="0" ixz="0" iyy="0.0025" iyz="0" izz="0.0045" />
        </inertial>
    </link>

    <link name="rear_right_wheel_link">
        <visual>
            <origin xyz="0 0 0" rpy="1.57079 0 0" />
            <geometry>
                <cylinder length="0.08" radius="0.108" />
            </geometry>
            <material name="mecanum_wheel">
                <color rgba="0.2 0.2 0.2 1.0" />
            </material>
        </visual>
        <visual>
            <origin xyz="0 0 0" rpy="0.785398 1.57079 0" />
            <geometry>
                <box size="0.15 0.02 0.02" />
            </geometry>
            <material name="roller">
                <color rgba="0.4 0.4 0.4 1.0" />
            </material>
        </visual>
        <collision>
            <origin xyz="0 0 0" rpy="1.57079 0 0" />
            <geometry>
                <cylinder length="0.08" radius="0.108" />
            </geometry>
        </collision>
        <inertial>
            <mass value="1.2" />
            <inertia ixx="0.0025" ixy="0" ixz="0" iyy="0.0025" iyz="0" izz="0.0045" />
        </inertial>
    </link>

    <joint name="front_left_wheel_joint" type="continuous">
        <parent link="base_link" />
        <child link="front_left_wheel_link" />
        <origin xyz="0.40 0.28 0" rpy="0 0 0" />
        <axis xyz="0 1 0" />
    </joint>

    <joint name="front_right_wheel_joint" type="continuous">
        <parent link="base_link" />
        <child link="front_right_wheel_link" />
        <origin xyz="0.40 -0.28 0" rpy="0 0 0" />
        <axis xyz="0 1 0" />
    </joint>

    <joint name="rear_left_wheel_joint" type="continuous">
        <parent link="base_link" />
        <child link="rear_left_wheel_link" />
        <origin xyz="-0.40 0.28 0" rpy="0 0 0" />
        <axis xyz="0 1 0" />
    </joint>

    <joint name="rear_right_wheel_joint" type="continuous">
        <parent link="base_link" />
        <child link="rear_right_wheel_link" />
        <origin xyz="-0.40 -0.28 0" rpy="0 0 0" />
        <axis xyz="0 1 0" />
    </joint>

    <gazebo reference="front_left_wheel_link">
        <material>Gazebo/DarkGrey</material>
        <collision>
            <surface>
                <friction>
                    <ode>
                        <mu1>0.8</mu1>
                        <mu2>0.03</mu2>
                        <fdir1>
                            <x>0.7071</x>
                            <y>0.7071</y>
                            <z>0.0</z>
                        </fdir1>
                        <kp value="10000000.0" />
                        <kd value="1.0" />
                    </ode>
                </friction>
                <contact>
                    <ode>
                        <kp>1e7</kp>
                        <kd>1.0</kd>
                        <min_depth>0.001</min_depth>
                    </ode>
                </contact>
            </surface>
        </collision>
    </gazebo>

    <gazebo reference="front_right_wheel_link">
        <material>Gazebo/DarkGrey</material>
        <collision>
            <surface>
                <friction>
                    <ode>
                        <mu1>0.8</mu1>
                        <mu2>0.03</mu2>
                        <fdir1>
                            <x>0.7071</x>
                            <y>-0.7071</y>
                            <z>0.0</z>
                        </fdir1>
                        <kp value="10000000.0" />
                        <kd value="1.0" />
                    </ode>
                </friction>
                <contact>
                    <ode>
                        <kp>1e7</kp>
                        <kd>1.0</kd>
                        <min_depth>0.001</min_depth>
                    </ode>
                </contact>
            </surface>
        </collision>
    </gazebo>

    <gazebo reference="rear_left_wheel_link">
        <material>Gazebo/DarkGrey</material>
        <collision>
            <surface>
                <friction>
                    <ode>
                        <mu1>0.8</mu1>
                        <mu2>0.03</mu2>
                        <fdir1>
                            <x>0.7071</x>
                            <y>-0.7071</y>
                            <z>0.0</z>
                        </fdir1>
                        <kp value="10000000.0" />
                        <kd value="1.0" />
                    </ode>
                </friction>
                <contact>
                    <ode>
                        <kp>1e7</kp>
                        <kd>1.0</kd>
                        <min_depth>0.001</min_depth>
                    </ode>
                </contact>
            </surface>
        </collision>
    </gazebo>

    <gazebo reference="rear_right_wheel_link">
        <material>Gazebo/DarkGrey</material>
        <collision>
            <surface>
                <friction>
                    <ode>
                        <mu1>0.8</mu1>
                        <mu2>0.03</mu2>
                        <fdir1>
                            <x>0.7071</x>
                            <y>0.7071</y>
                            <z>0.0</z>
                        </fdir1>
                        <kp value="10000000.0" />
                        <kd value="1.0" />
                    </ode>
                </friction>
                <contact>
                    <ode>
                        <kp>1e7</kp>
                        <kd>1.0</kd>
                        <min_depth>0.001</min_depth>
                    </ode>
                </contact>
            </surface>
        </collision>
    </gazebo>

    <gazebo reference="laser_link">
        <material>Gazebo/Purple</material>
        <sensor name="laser_sensor" type="ray">
            <always_on>true</always_on>
            <visualize>true</visualize>
            <update_rate>20</update_rate>
            <pose>0 0 0 0 0 0</pose>
            <ray>
                <scan>
                    <horizontal>
                        <samples>720</samples>
                        <resolution>1.0</resolution>
                        <time_increment>0.000069</time_increment>
                        <min_angle>-3.14159</min_angle>
                        <max_angle>3.14159</max_angle>
                    </horizontal>
                </scan>
                <range>
                    <min>0.15</min>
                    <max>15.0</max>
                    <resolution>0.01</resolution>
                </range>
                <noise>
                    <type>gaussian</type>
                    <mean>0.0</mean>
                    <stddev>0.001</stddev>
                </noise>
            </ray>
            <plugin name="gazebo_ros_head_laser_controller" filename="libgazebo_ros_ray_sensor.so">
                <ros>
                    <remapping>~/out:=scan</remapping>
                </ros>
                <topicName>scan</topicName>
                <frameName>laser_link</frameName>
                <frame_name>laser_link</frame_name>
                <output_type>sensor_msgs/LaserScan</output_type>
                <min_range>0.15</min_range>
                <max_range>15.0</max_range>
                <angle_min>-3.14159</angle_min>
                <angle_max>3.14159</angle_max>
                <scan_time>0.05</scan_time>
            </plugin>
        </sensor>
    </gazebo>

    <gazebo>
        <physics type="ode">
            <max_step_size>0.01</max_step_size>
            <real_time_factor>1.0</real_time_factor>
            <real_time_update_rate>100</real_time_update_rate>
        </physics>
    </gazebo>

    <ros2_control name="GazeboSystem" type="system">
        <hardware>
            <plugin>gazebo_ros2_control/GazeboSystem</plugin>
        </hardware>

        <joint name="front_left_wheel_joint">
            <command_interface name="velocity" />
            <state_interface name="position" />
            <state_interface name="velocity" />
        </joint>

        <joint name="front_right_wheel_joint">
            <command_interface name="velocity" />
            <state_interface name="position" />
            <state_interface name="velocity" />
        </joint>

        <joint name="rear_left_wheel_joint">
            <command_interface name="velocity" />
            <state_interface name="position" />
            <state_interface name="velocity" />
        </joint>

        <joint name="rear_right_wheel_joint">
            <command_interface name="velocity" />
            <state_interface name="position" />
            <state_interface name="velocity" />
        </joint>
    </ros2_control>

    <gazebo>
        <plugin name="gazebo_ros2_control" filename="libgazebo_ros2_control.so">
            <parameters>
                /home/kisdy/projects/agv_localization_ws/install/jzt_robot/share/jzt_robot/config/mecanum_controllers.yaml
            </parameters>
        </plugin>
    </gazebo>

</robot>