<?xml version="1.0"?>
<robot xmlns:xacro="http://ros.org/wiki/xacro">

    <!-- ==================== 左轮 ==================== -->
    <link name="left_wheel_link">
        <visual>
            <origin xyz="0 0 0" rpy="${PI_2} 0 0" />
            <geometry>
                <cylinder length="${wheel_width}" radius="${wheel_radius}" />
            </geometry>
            <material name="blue" />
        </visual>
        <collision>
            <origin xyz="0 0 0" rpy="${PI_2} 0 0" />
            <geometry>
                <cylinder length="${wheel_width}" radius="${wheel_radius}" />
            </geometry>
        </collision>
        <inertial>
            <mass value="${wheel_mass}" />
            <xacro:cylinder_inertia m="${wheel_mass}" r="${wheel_radius}" l="${wheel_width}" />
        </inertial>
    </link>

    <joint name="left_wheel_joint" type="continuous">
        <parent link="base_link" />
        <child link="left_wheel_link" />
        <origin xyz="${wheel_x} ${wheel_y} ${wheel_z}" />
        <axis xyz="0 1 0" />
    </joint>

    <!-- ==================== 右轮 ==================== -->
    <link name="right_wheel_link">
        <visual>
            <origin xyz="0 0 0" rpy="${PI_2} 0 0" />
            <geometry>
                <cylinder length="${wheel_width}" radius="${wheel_radius}" />
            </geometry>
            <material name="blue" />
        </visual>
        <collision>
            <origin xyz="0 0 0" rpy="${PI_2} 0 0" />
            <geometry>
                <cylinder length="${wheel_width}" radius="${wheel_radius}" />
            </geometry>
        </collision>
        <inertial>
            <mass value="${wheel_mass}" />
            <xacro:cylinder_inertia m="${wheel_mass}" r="${wheel_radius}" l="${wheel_width}" />
        </inertial>
    </link>

    <joint name="right_wheel_joint" type="continuous">
        <parent link="base_link" />
        <child link="right_wheel_link" />
        <origin xyz="${wheel_x} ${-wheel_y} ${wheel_z}" />
        <axis xyz="0 1 0" />
    </joint>

    <!-- ==================== 脚轮宏 ==================== -->
    <xacro:macro name="caster_wheel" params="prefix x y z">
        <link name="${prefix}_link">
            <visual>
                <origin xyz="0 0 0" rpy="${PI_2} 0 0" />
                <geometry>
                    <sphere radius="${caster_radius}" />
                </geometry>
                <material name="black" />
            </visual>
            <collision>
                <origin xyz="0 0 0" rpy="${PI_2} 0 0" />
                <geometry>
                    <sphere radius="${caster_radius}" />
                </geometry>
            </collision>
            <inertial>
                <mass value="${caster_mass}" />
                <xacro:sphere_inertia m="${caster_mass}" r="${caster_radius}" />
            </inertial>
        </link>

        <joint name="${prefix}_joint" type="fixed">
            <parent link="base_link" />
            <child link="${prefix}_link" />
            <origin xyz="${x} ${y} ${z}" />
        </joint>
    </xacro:macro>

    <!-- 四个脚轮 -->
    <xacro:caster_wheel prefix="caster_front_right" x="0.28" y="0.18" z="-0.076" />
    <xacro:caster_wheel prefix="caster_front_left"  x="0.28" y="-0.18" z="-0.076" />
    <xacro:caster_wheel prefix="caster_rear_right"  x="-0.28" y="0.18" z="-0.076" />
    <xacro:caster_wheel prefix="caster_rear_left"   x="-0.28" y="-0.18" z="-0.076" />

</robot>
